<mujoco model="fr3">
    <compiler angle="radian" meshdir="assets"/>

    <option integrator="implicitfast"/>

    <default>
        <default class="fr3">
            <!-- Overwritten in joints 5, 6, and 7. -->
            <joint damping="0.21" armature="0.195" frictionloss="1.137"/>
            <position inheritrange="1"/>
            <default class="visual">
                <geom type="mesh" group="2" contype="0" conaffinity="0"/>
            </default>
            <default class="collision">
                <geom type="mesh" group="3" mass="0" density="0"/>
                <default class="fingertip_pad_collision_1">
                    <geom type="box" size="0.0085 0.004 0.0085" pos="0 0.0055 0.0445"/>
                </default>
                <default class="fingertip_pad_collision_2">
                    <geom type="box" size="0.003 0.002 0.003" pos="0.0055 0.002 0.05"/>
                </default>
                <default class="fingertip_pad_collision_3">
                    <geom type="box" size="0.003 0.002 0.003" pos="-0.0055 0.002 0.05"/>
                </default>
                <default class="fingertip_pad_collision_4">
                    <geom type="box" size="0.003 0.002 0.0035" pos="0.0055 0.002 0.0395"/>
                </default>
                <default class="fingertip_pad_collision_5">
                    <geom type="box" size="0.003 0.002 0.0035" pos="-0.0055 0.002 0.0395"/>
                </default>
            </default>
            <site size="0.001" rgba="0.5 0.5 0.5 0.3" group="4"/>
            <default class="finger">
                <joint axis="0 1 0" type="slide" range="0 0.04"/>
            </default>
        </default>
    </default>

    <asset>
        <material name="black" rgba=".2 .2 .2 1"/>
        <material name="white" rgba="1 1 1 1"/>
        <material name="off_white" rgba="0.901961 0.921569 0.929412 1"/>
        <material name="red" rgba="1 0.072272 0.039546 1"/>
        <material name="gray" rgba="0.863156 0.863156 0.863157 1"/>
        <material name="button_green" rgba="0.102241 0.571125 0.102242 1"/>
        <material name="button_red" rgba="0.520996 0.008023 0.013702 1"/>
        <material name="button_blue" rgba="0.024157 0.445201 0.737911 1"/>

        <mesh name="link0_0" file="link0_0_vis.obj"/>
        <mesh name="link0_1" file="link0_1_vis.obj"/>
        <mesh name="link0_2" file="link0_2_vis.obj"/>
        <mesh name="link0_3" file="link0_3_vis.obj"/>
        <mesh name="link0_4" file="link0_4_vis.obj"/>
        <mesh name="link0_5" file="link0_5_vis.obj"/>
        <mesh name="link0_6" file="link0_6_vis.obj"/>
        <mesh name="link1" file="link1_vis.obj"/>
        <mesh name="link2" file="link2_vis.obj"/>
        <mesh name="link3_0" file="link3_0_vis.obj"/>
        <mesh name="link3_1" file="link3_1_vis.obj"/>
        <mesh name="link4_0" file="link4_0_vis.obj"/>
        <mesh name="link4_1" file="link4_1_vis.obj"/>
        <mesh name="link5_0" file="link5_0_vis.obj"/>
        <mesh name="link5_1" file="link5_1_vis.obj"/>
        <mesh name="link5_2" file="link5_2_vis.obj"/>
        <mesh name="link6_0" file="link6_0_vis.obj"/>
        <mesh name="link6_1" file="link6_1_vis.obj"/>
        <mesh name="link6_2" file="link6_2_vis.obj"/>
        <mesh name="link6_3" file="link6_3_vis.obj"/>
        <mesh name="link6_4" file="link6_4_vis.obj"/>
        <mesh name="link6_5" file="link6_5_vis.obj"/>
        <mesh name="link6_6" file="link6_6_vis.obj"/>
        <mesh name="link6_7" file="link6_7_vis.obj"/>
        <mesh name="link7_0" file="link7_0_vis.obj"/>
        <mesh name="link7_1" file="link7_1_vis.obj"/>
        <mesh name="link7_2" file="link7_2_vis.obj"/>
        <mesh name="link7_3" file="link7_3_vis.obj"/>
        <mesh name="hand_0" file="hand_0_vis.obj"/>
        <mesh name="hand_1" file="hand_1_vis.obj"/>
        <mesh name="hand_2" file="hand_2_vis.obj"/>
        <mesh name="hand_3" file="hand_3_vis.obj"/>
        <mesh name="hand_4" file="hand_4_vis.obj"/>
        <mesh name="finger_0" file="finger_0_vis.obj"/>
        <mesh name="finger_1" file="finger_1_vis.obj"/>

        <mesh name="link0_coll" file="link0_coll.stl"/>
        <mesh name="link1_coll" file="link1_coll.stl"/>
        <mesh name="link2_coll" file="link2_coll.stl"/>
        <mesh name="link3_coll" file="link3_coll.stl"/>
        <mesh name="link4_coll" file="link4_coll.stl"/>
        <mesh name="link5_coll" file="link5_coll.stl"/>
        <mesh name="link6_coll" file="link6_coll.stl"/>
        <mesh name="link7_coll" file="link7_coll.stl"/>
        <mesh name="hand_coll" file="hand_coll.stl"/>
    </asset>

    <worldbody>
        <body name="base" childclass="fr3">
            <body name="fr3_link0">
                <geom mesh="link0_0" material="black" class="visual"/>
                <geom mesh="link0_1" material="white" class="visual"/>
                <geom mesh="link0_2" material="white" class="visual"/>
                <geom mesh="link0_3" material="white" class="visual"/>
                <geom mesh="link0_4" material="white" class="visual"/>
                <geom mesh="link0_5" material="red" class="visual"/>
                <geom mesh="link0_6" material="black" class="visual"/>
                <geom name="fr3_link0_collision" mesh="link0_coll" class="collision"/>
                <body name="fr3_link1" pos="0 0 0.333">
                    <inertial pos="4.128e-07 -0.0181251 -0.0386036" quat="0.998098 -0.0605364 0.00380499 0.0110109"
                              mass="2.92747"
                              diaginertia="0.0239286 0.0227246 0.00610634"/>
                    <joint name="fr3_joint1" axis="0 0 1" range="-2.7437 2.7437" actuatorfrcrange="-87 87"/>
                    <geom name="fr3_link1_collision" class="collision" mesh="link1_coll"/>
                    <geom material="white" mesh="link1" class="visual"/>
                    <body name="fr3_link2" quat="1 -1 0 0">
                        <inertial pos="0.00318289 -0.0743222 0.00881461" quat="0.502599 0.584437 -0.465998 0.434366"
                                  mass="2.93554"
                                  diaginertia="0.0629567 0.0411924 0.0246371"/>
                        <joint name="fr3_joint2" axis="0 0 1" range="-1.7837 1.7837" actuatorfrcrange="-87 87"/>
                        <geom material="white" mesh="link2" class="visual"/>
                        <geom name="fr3_link2_collision" class="collision" mesh="link2_coll"/>
                        <body name="fr3_link3" pos="0 -0.316 0" quat="1 1 0 0">
                            <inertial pos="0.0407016 -0.00482006 -0.0289731" quat="0.921025 -0.244161 0.155272 0.260745"
                                      mass="2.2449"
                                      diaginertia="0.0267409 0.0189869 0.0171587"/>
                            <joint name="fr3_joint3" axis="0 0 1" range="-2.9007 2.9007" actuatorfrcrange="-87 87"/>
                            <geom mesh="link3_0" material="white" class="visual"/>
                            <geom mesh="link3_1" material="black" class="visual"/>
                            <geom name="fr3_link3_collision" class="collision" mesh="link3_coll"/>
                            <body name="fr3_link4" pos="0.0825 0 0" quat="1 1 0 0">
                                <inertial pos="-0.0459101 0.0630493 -0.00851879"
                                          quat="0.438018 0.803311 0.00937812 0.403414"
                                          mass="2.6156" diaginertia="0.05139 0.0372717 0.0160047"/>
                                <joint name="fr3_joint4" axis="0 0 1" range="-3.0421 -0.1518"
                                       actuatorfrcrange="-87 87"/>
                                <geom mesh="link4_0" material="white" class="visual"/>
                                <geom mesh="link4_1" material="black" class="visual"/>
                                <geom name="fr3_link4_collision" class="collision" mesh="link4_coll"/>
                                <body name="fr3_link5" pos="-0.0825 0.384 0" quat="1 -1 0 0">
                                    <inertial pos="-0.00160396 0.0292536 -0.0972966"
                                              quat="0.919031 0.125604 0.0751531 -0.366003"
                                              mass="2.32712" diaginertia="0.0579335 0.0449144 0.0130634"/>
                                    <joint name="fr3_joint5" axis="0 0 1" range="-2.8065 2.8065"
                                           actuatorfrcrange="-12 12"
                                           armature="0.074" frictionloss="0.763"/>
                                    <geom mesh="link5_0" material="white" class="visual"/>
                                    <geom mesh="link5_1" material="white" class="visual"/>
                                    <geom mesh="link5_2" material="black" class="visual"/>
                                    <geom name="fr3_link5_collision" class="collision" mesh="link5_coll"/>
                                    <body name="fr3_link6" quat="1 1 0 0">
                                        <inertial pos="0.0597131 -0.0410295 -0.0101693"
                                                  quat="0.621301 0.552665 0.510011 0.220081"
                                                  mass="1.81704" diaginertia="0.0175039 0.0161123 0.00193529"/>
                                        <joint name="fr3_joint6" axis="0 0 1" range="0.5445 4.5169"
                                               actuatorfrcrange="-12 12"
                                               armature="0.074" frictionloss="0.44"/>
                                        <geom mesh="link6_0" material="button_green" class="visual"/>
                                        <geom mesh="link6_1" material="white" class="visual"/>
                                        <geom mesh="link6_2" material="white" class="visual"/>
                                        <geom mesh="link6_3" material="gray" class="visual"/>
                                        <geom mesh="link6_4" material="button_red" class="visual"/>
                                        <geom mesh="link6_5" material="white" class="visual"/>
                                        <geom mesh="link6_6" material="black" class="visual"/>
                                        <geom mesh="link6_7" material="button_blue" class="visual"/>
                                        <geom name="fr3_link6_collision" class="collision" mesh="link6_coll"/>
                                        <body name="fr3_link7" pos="0.088 0 0" quat="1 1 0 0">
                                            <inertial pos="0.00452258 0.00862619 -0.0161633"
                                                      quat="0.727579 0.0978688 -0.24906 0.63168"
                                                      mass="0.627143"
                                                      diaginertia="0.000223836 0.000223642 5.64132e-07"/>
                                            <joint name="fr3_joint7" axis="0 0 1" range="-3.0159 3.0159"
                                                   actuatorfrcrange="-12 12"
                                                   armature="0.074" frictionloss="0.248"/>
                                            <geom mesh="link7_0" material="black" class="visual"/>
                                            <geom mesh="link7_1" material="white" class="visual"/>
                                            <geom mesh="link7_2" material="white" class="visual"/>
                                            <geom mesh="link7_3" material="black" class="visual"/>
                                            <geom name="fr3_link7_collision" class="collision" mesh="link7_coll"/>
                                            <body name="hand" pos="0 0 0.107" quat="0.9238795 0 0 -0.3826834">
                                                <inertial mass="0.73" pos="-0.01 0 0.03"
                                                          diaginertia="0.001 0.0025 0.0017"/>
                                                <geom mesh="hand_0" material="off_white" class="visual"/>
                                                <geom mesh="hand_1" material="black" class="visual"/>
                                                <geom mesh="hand_2" material="black" class="visual"/>
                                                <geom mesh="hand_3" material="white" class="visual"/>
                                                <geom mesh="hand_4" material="off_white" class="visual"/>
                                                <geom mesh="hand_coll" class="collision"/>
                                                <body name="left_finger" pos="0 0 0.0584">
                                                    <inertial mass="0.015" pos="0 0 0"
                                                              diaginertia="2.375e-6 2.375e-6 7.5e-7"/>
                                                    <joint name="finger_joint1" class="finger"/>
                                                    <geom mesh="finger_0" material="off_white" class="visual"/>
                                                    <geom mesh="finger_1" material="black" class="visual"/>
                                                    <geom mesh="finger_0" class="collision"/>
                                                    <geom class="fingertip_pad_collision_1"/>
                                                    <geom class="fingertip_pad_collision_2"/>
                                                    <geom class="fingertip_pad_collision_3"/>
                                                    <geom class="fingertip_pad_collision_4"/>
                                                    <geom class="fingertip_pad_collision_5"/>
                                                </body>
                                                <body name="right_finger" pos="0 0 0.0584" quat="0 0 0 1">
                                                    <inertial mass="0.015" pos="0 0 0"
                                                              diaginertia="2.375e-6 2.375e-6 7.5e-7"/>
                                                    <joint name="finger_joint2" class="finger"/>
                                                    <geom mesh="finger_0" material="off_white" class="visual"/>
                                                    <geom mesh="finger_1" material="black" class="visual"/>
                                                    <geom mesh="finger_0" class="collision"/>
                                                    <geom class="fingertip_pad_collision_1"/>
                                                    <geom class="fingertip_pad_collision_2"/>
                                                    <geom class="fingertip_pad_collision_3"/>
                                                    <geom class="fingertip_pad_collision_4"/>
                                                    <geom class="fingertip_pad_collision_5"/>
                                                </body>
                                            </body>
                                        </body>
                                    </body>
                                </body>
                            </body>
                        </body>
                    </body>
                </body>
            </body>
        </body>
    </worldbody>

    <actuator>
        <position class="fr3" name="fr3_joint1" joint="fr3_joint1" kp="4500" kv="450"/>
        <position class="fr3" name="fr3_joint2" joint="fr3_joint2" kp="4500" kv="450"/>
        <position class="fr3" name="fr3_joint3" joint="fr3_joint3" kp="3500" kv="350"/>
        <position class="fr3" name="fr3_joint4" joint="fr3_joint4" kp="3500" kv="350"/>
        <position class="fr3" name="fr3_joint5" joint="fr3_joint5" kp="2000" kv="200"/>
        <position class="fr3" name="fr3_joint6" joint="fr3_joint6" kp="2000" kv="200"/>
        <position class="fr3" name="fr3_joint7" joint="fr3_joint7" kp="2000" kv="200"/>
        <general class="fr3" name="hand" tendon="split" forcerange="-140 140" ctrlrange="0 255"
                 gainprm="0.01568627451 0 0" biasprm="0 -100 -10"/>
    </actuator>

    <tendon>
        <fixed name="split">
            <joint joint="finger_joint1" coef="0.5"/>
            <joint joint="finger_joint2" coef="0.5"/>
        </fixed>
    </tendon>

    <equality>
        <joint joint1="finger_joint1" joint2="finger_joint2" solimp="0.95 0.99 0.001" solref="0.005 1"/>
    </equality>

    <contact>
        <exclude body1="fr3_link0" body2="fr3_link1"/>
    </contact>

    <keyframe>
        <key name="home" qpos="0 0 0 -1.57079 0 1.57079 -0.7853 0.04 0.04" ctrl="0 0 0 -1.57079 0 1.57079 -0.7853 255"/>
    </keyframe>
</mujoco>
